Workbook

Sheet Executive Summary 
B1: Coffee C® Futures & Options: Quantitative Risk Report
A5: # | B5: The Integrated Market Outlook
B6: This report synthesizes three distinct quantitative layers to evaluate the six-month horizon for Coffee C® futures and options. By bridging the gap between theoretical fair value and stochastic forecasting, we provide a clear view of the market's "expected gravity" versus its "extreme risk potential."
A9: # | B9: Summary of Key Metrics ( The "Results")
B10: Project Component | D10: Key Metric | F10: Interpretation
B11: Project 1: Cost of Carry | D11: ='Cost of Carry Model'!F5 -> 3.0081028 | F11: The "No-Arbitrage" future price based on holding costs.
B13: Project 2: Black Schole Model | D13: ='Black-Scholes Model'!J12 -> 0.34414844 | F13: The cost of time and market volatility (The Hedge).
B15: Project 3: M C Simulation | D15: ='Monte Carlo Simulation'!J11 -> 2.9987364 | F15: The expected "Center of Gravity" across 10,000 scenarios.
A17: # | B17: Visual Proof (The "Evidence")
B33: Figure 1: Price Path Dispersion (The Journey) | I33: Figure 2: Terminal Price Distribution (The Destination)
B35: Integrated Risk Analysis
B36: The dual-lens view above provides a comprehensive 'stress test' of our strategy. Figure 1 illustrates the 'Fan of Uncertainty' over the 126-day trading horizon, visualizing the 10,000 unique paths the market could take. While the paths appear chaotic, Figure 2 settles this noise into a clear statistical distribution at maturity.
B40: Together, they prove that while the market’s center of gravity is near our fair value, the upside risk (the 'fat tails' in Fig 2) is significant. This confirms that our $0.34 premium is a vital insurance policy to protect our procurement budget against the extreme price spikes seen in Fig 1.
A43: # | B43: Strategic Recommendations (The "Action")
B44: 1. Risk Mitigation: Given the high volatility (39.30%), the $0.34 premium is a reasonable "insurance policy" to cap procurement costs at $2.95.
B45: 2. Arbitrage Monitoring: If the market price for 6-month futures trades significantly higher than $3.01, it indicates an "overpriced" scenario where selling futures could be profitable.
B47: 3. Dynamic Updating: These models should be refreshed weekly to account for Time Decay (Theta) and shifting volatility levels.
A49: # | B49: Technical Appendix (The "How")
B50: The Hybrid Quantitative Workflow
B51: 1. Excel as the "Control Center": Used for initial data ingestion, Cost of Carry calculations, and Black-Scholes closed-form solutions.
B52: 2. Python as the "Stress Test Engine": Used to execute 10,000 Monte Carlo iterations to provide a high-fidelity statistical check on the static Excel models.
B54: Model Specifications
B55: 1. Stochastic Process: The simulation utilizes Geometric Brownian Motion (GBM), assuming coffee price returns are log-normally distributed.
B56: 2. Volatility Calibration: Annualized volatility (sigma) is dynamically calculated in Python: sigma = STDEV(Log Returns) * sqrt(252).
B57: 3. Time Step Logic: I utilized a time step (dt) of T/252, simulating exactly 126 trading days (T=0.5).
B59: This model bridges the gap between the coffee warehouse and the trading floor. It ensures our buying strategy is based on actual logistics, while our insurance (the option) is backed by 10,000 simulations. We’ve turned market uncertainty into a manageable plan.

Sheet Report Dashboard
B1: Analyzing the Fair Value of Coffee C® Futures: A Cost of Carry Framework
A3: # | B3: Project Overview: Calculate the futures price for a coffee contract maturing in six months using the current spot price, the risk-free interest rate, and the estimated storage costs.
A5: # | B5: Why Calculate the Coffee Futures Price?
B6: This model determines the "fair value" of a coffee contract for delivery in six months. By evaluating the current spot price ($2.94) against the costs of "carrying" the physical commodity-specifically the risk-free interest rate and storage expenses-we can determine if the market's future price is justified by physical reality. This helps traders decide whether it is more cost-effective to buy coffee today and store it, or simply buy a futures contract for later delivery.
A9: # | B9: Futures Valuation Overview
B10: Spot Price (S0): | E10: 2.94
B11: Risk-Free Rate (r): | E11: 0.0358
B12: Storage Cost (d): | E12: 0.01
B13: Time to Maturity (T): | E13: 0.5
B14: The calculated Fair Futures Price (Ft) is $3.01. This indicates that a buyer should expect to pay a $0.07 premium over the current spot price to account for the costs of financing and warehousing the coffee for the next half-year.
A16: # | B16: Why Calculating the Carry Components is Important?
B17: 1. The Cost of Financing (r = 3.58%)
B18: Interpretation: This represents the "opportunity cost" of capital. If you buy physical coffee today, your money is "locked up" in beans rather than earning interest in a safe 6-month Treasury bill. The model adds this lost interest to the future price of the coffee to ensure the investment remains balanced against a risk-free alternative.
B21: 2. The Cost of Physical Storage (d = 1.00%)
B22: Interpretation: Unlike stocks or bonds, coffee is a physical asset that requires climate-controlled silos and insurance. These "carry costs" are added to the spot price because the futures contract allows the buyer to avoid these immediate logistics expenses, pushing the fair price higher as the time to delivery increases.
A24: # | B24: Market Scenario & Arbitrage Analysis
B25: 1. Contango Market Structure
B26: Interpretation: Because my calculated futures price ($3.01) is higher than the current spot price ($2.94), the market is in "Contango." This is normal for storable commodities like coffee. It tells us there is no immediate shortage; instead, the market is adequately supplied, and the price difference is simply reflecting the "rent" paid for time and storage space.
B29: 2. Theoretical Arbitrage Opportunity
B30: Interpretation: If we look at a real-time exchange like the ICE and see the 6-month futures trading at $3.10 (higher than your calculated $3.01), the market is "overpriced". A professional trader might sell that expensive futures contract and buy the physical coffee today to "lock in" a risk-free profit. Conversely, if the market price is below $3.01, it suggests a supply squeeze where people are willing to pay a premium for coffee now rather than later.
B34: Evaluating Coffee® Call Option Performance: A Quantitative Perspective
A37: # | B37: Project Overview: Price a call option on a coffee futures contract using the current spot price, strike price, risk-free rate, time to maturity, and volatility.
A39: # | B39: Why Price a Coffee Call Option?
B40: This model evaluates a European call option on Coffee C® futures, a global benchmark for Arabica coffee. By analyzing current spot prices ($2.94) against a target strike price ($2.95), we gain a sophisticated understanding of how time value and market volatility drive the "premium" of a commodity contract. In a high-volatility environment (39.29%), this option serves as a critical hedging tool against potential supply shocks or weather-driven price spikes.
A43: # | B43: Option Valuation Overview
B44: Strike Price (Xt) | E44: ='Black-Scholes Model'!G7 -> 2.95
B45: N(d1) | E45: ='Black-Scholes Model'!J9 -> 0.57579141
B46: N(d2) | E46: ='Black-Scholes Model'!J10 -> 0.46543627
B47: Spot Price (S0): | E47: 2.94
B48: Risk-Free Rate (r): | E48: 0.0358
B49: Storage Cost (d): | E49: 0.01
B50: Time to Maturity (T): | E50: 0.5 | F50: Years (6 Months)
B51: Annualized Volatility : | E51: 0.3929
B52: The calculated Option Price (Present Value) is $0.34. Even though the spot price is currently slightly below the strike (making it "out-of-the-money"), the option commands a premium because of the significant time value and the probability of a price recovery before the six-month expiration.
A54: # | B54: Why Calculating N(d1) and N(d2) is Important?
B55: 1. Delta (N(d1) 0.57): The Sensitivity Measure
B56: This is our most accurate measure of price sensitivity. It tells us that for every $1 move in the underlying coffee spot price, the option's value is expected to move by approximately $0.57. This helps traders understand how much of the market's "pulse" the option captures.
B59: 2. Probability of Exercise (N(d2) 0.46): The Market's "Odds"
B60: This represents the risk-neutral probability that the option will finish "in-the-money." At 46%, the market suggests a nearly balanced outlook, where there is a strong possibility that coffee prices will climb above the $2.95 threshold by maturity.
A62: # | B62: Market Scenario & Risk Analysis
...

Sheet Cost of Carry Model
B1: A Costof Carry Framework
B4: Inputs | E4: Key Measure
B5: Time to maturity (T) | C5: 0.5 | E5: Future Price (Ft) | F5: =C6*EXP((C7+C8)*0.5) -> 3.0081028
B6: Spot Price (S0) | C6: 2.94
B7: Risk-free rate (r) | C7: 0.0358
B8: Storage Cost (d) | C8: 0.01

Sheet Black-Scholes Model
B1: Evaluating Coffee® Call Option Performance: Black-Schole Approach
B4: Date | C4: Close | D4: Log Returns | F4: Inputs | I4: Key Measure
B5: 45694 | C5: 403.95001 | F5: Time to maturity (T) | G5: 0.5 | I5: Volatility | J5: =_xlfn.STDEV.S(D6:D257) -> 0.024756005
B6: 45695 | C6: 404.35001 | D6: =LN(C6/C5) -> 0.00098971649 | F6: Spot Price (S0) | G6: 2.94 | I6: Annualize Volatility | J6: =J5*SQRT(252) -> 0.3929894
B7: 45698 | C7: 429.04999 | D7: =LN(C7/C6) -> 0.059292579 | F7: Strike Price (Xt) | G7: 2.95 | I7: d1 | J7: =(LN(G6/G7)+(G8+((J6^2)/2))*G5)/(J6*SQRT(G5)) -> 0.19113838
B8: 45699 | C8: 413.45001 | D8: =LN(C8/C7) -> -0.037036816 | F8: Risk-free rate (r) | G8: 0.0358 | I8: d2 | J8: =J7-(J6*SQRT(G5)) -> -0.086747089
B9: 45700 | C9: 431.79999 | D9: =LN(C9/C8) -> 0.043425872 | I9: N(d1) | J9: =_xlfn.NORM.S.DIST(J7,TRUE) -> 0.57579141
B10: 45701 | C10: 438.89999 | D10: =LN(C10/C9) -> 0.016309093 | I10: N(d2) | J10: =_xlfn.NORM.S.DIST(J8,TRUE) -> 0.46543627
B11: 45702 | C11: 419.75 | D11: =LN(C11/C10) -> -0.044612287
B12: 45706 | C12: 419 | D12: =LN(C12/C11) -> -0.001788376 | I12: Call Price (C) | J12: =G6*J9-G7*(EXP(-G8*G5))*J10 -> 0.34414844
B13: 45707 | C13: 417.89999 | D13: =LN(C13/C12) -> -0.0026287651
B14: 45708 | C14: 395.75 | D14: =LN(C14/C13) -> -0.054459456
B15: 45709 | C15: 400 | D15: =LN(C15/C14) -> 0.010681848
B16: 45712 | C16: 393.79999 | D16: =LN(C16/C15) -> -0.015621412
B17: 45713 | C17: 380.5 | D17: =LN(C17/C16) -> -0.034356958
B18: 45714 | C18: 379.45001 | D18: =LN(C18/C17) -> -0.0027633093
B19: 45715 | C19: 378.75 | D19: =LN(C19/C18) -> -0.0018465112
B20: 45716 | C20: 379.04999 | D20: =LN(C20/C19) -> 0.00079173347
B21: 45719 | C21: 392.70001 | D21: =LN(C21/C20) -> 0.035377902
B22: 45720 | C22: 403.75 | D22: =LN(C22/C21) -> 0.027749882
B23: 45721 | C23: 415.5 | D23: =LN(C23/C22) -> 0.02868674
B24: 45722 | C24: 393 | D24: =LN(C24/C23) -> -0.055673002
... B257: 46059 | C257: 286.70001 | D257: =LN(C257/C256) -> -0.072961206

Sheet Monte Carlo Simulation
B1: Stochastic Forecasting: Coffee Price Path Scenarios & Market Uncertainty
B4: Date | C4: Close | D4: Log Returns | F4: Inputs | I4: Key Measure | L4: The Trading Days | M4: Scenario 1 | N4: Scenario 2 | O4: Scenario 3 | P4: Scenario 4 | Q4: Scenario 5 | R4: Scenario 6 | S4: Scenario 7 | T4: Scenario 8 | U4: Scenario 9 | V4: Scenario 10 | W4: Scenario 11 | X4: Scenario 12 | Y4: Scenario 13 | Z4: Scenario 14 | AA4: Scenario 15 | AB4: Scenario 16 | AC4: Scenario 17 | AD4: Scenario 18 | AE4: Scenario 19 | AF4: Scenario 20 | AG4: Scenario 21 | AH4: Scenario 22 | AI4: Scenario 23 | AJ4: Scenario 24 | AK4: Scenario 25 | AL4: Scenario 26 | AM4: Scenario 27 | AN4: Scenario 28 | AO4: Scenario 29 | AP4: Scenario 30 | AQ4: Scenario 31 | AR4: Scenario 32 | AS4: Scenario 33 | AT4: Scenario 34 | AU4: Scenario 35 | AV4: Scenario 36 | AW4: Scenario 37 | AX4: Scenario 38 | AY4: Scenario 39 | AZ4: Scenario 40
B5: 45694 | C5: 403.95001 | F5: Initial Price (S0) | G5: 2.94 | I5: Volatility | J5: =_xlfn.STDEV.S(D6:D257) -> 0.024756005 | L5: Day 1 | M5: 2.94 | N5: 2.94 | O5: 2.94 | P5: 2.94 | Q5: 2.94 | R5: 2.94 | S5: 2.94 | T5: 2.94 | U5: 2.94 | V5: 2.94 | W5: 2.94 | X5: 2.94 | Y5: 2.94 | Z5: 2.94 | AA5: 2.94 | AB5: 2.94 | AC5: 2.94 | AD5: 2.94 | AE5: 2.94 | AF5: 2.94 | AG5: 2.94 | AH5: 2.94 | AI5: 2.94 | AJ5: 2.94 | AK5: 2.94 | AL5: 2.94 | AM5: 2.94 | AN5: 2.94 | AO5: 2.94 | AP5: 2.94 | AQ5: 2.94 | AR5: 2.94 | AS5: 2.94 | AT5: 2.94 | AU5: 2.94 | AV5: 2.94 | AW5: 2.94 | AX5: 2.94 | AY5: 2.94 | AZ5: 2.94
B6: 45695 | C6: 404.35001 | D6: =LN(C6/C5) -> 0.00098971649 | F6: Risk-free rate (r) | G6: 0.0358 | I6: Annualize Volatility | J6: =J5*SQRT(252) -> 0.3929894 | L6: Day 2 | M6: =M5*EXP(($G$6-0.5*$J$6^2)*$G$7+($J$6*SQRT($G$7)*_xlfn.NORM.S.INV(RAND()))) -> 2.9231767 | N6: =N5*EXP(($G$6-0.5*$J$6^2)*$G$7+($J$6*SQRT($G$7)*_xlfn.NORM.S.INV(RAND()))) -> 3.0272209 | O6: =O5*EXP(($G$6-0.5*$J$6^2)*$G$7+($J$6*SQRT($G$7)*_xlfn.NORM.S.INV(RAND()))) -> 2.9470202 | P6: =P5*EXP(($G$6-0.5*$J$6^2)*$G$7+($J$6*SQRT($G$7)*_xlfn.NORM.S.INV(RAND()))) -> 2.9859691 | Q6: =Q5*EXP(($G$6-0.5*$J$6^2)*$G$7+($J$6*SQRT($G$7)*_xlfn.NORM.S.INV(RAND()))) -> 2.9455478 | R6: =R5*EXP(($G$6-0.5*$J$6^2)*$G$7+($J$6*SQRT($G$7)*_xlfn.NORM.S.INV(RAND()))) -> 2.9875555 | S6: =S5*EXP(($G$6-0.5*$J$6^2)*$G$7+($J$6*SQRT($G$7)*_xlfn.NORM.S.INV(RAND()))) -> 3.0103412 | T6: =T5*EXP(($G$6-0.5*$J$6^2)*$G$7+($J$6*SQRT($G$7)*_xlfn.NORM.S.INV(RAND()))) -> 2.9494142 | ... AZ6: =AZ5*EXP(($G$6-0.5*$J$6^2)*$G$7+($J$6*SQRT($G$7)*_xlfn.NORM.S.INV(RAND()))) -> 2.9317664
B7: 45698 | C7: 429.04999 | D7: =LN(C7/C6) -> 0.059292579 | F7: Time (dt) | G7: =1/252 -> 0.003968254 | I7: Strike Price (Xt) | J7: 2.95 | L7: Day 3 | M7: =M6*EXP(($G$6-0.5*$J$6^2)*$G$7+($J$6*SQRT($G$7)*_xlfn.NORM.S.INV(RAND()))) -> 2.9448267 | N7: =N6*EXP(($G$6-0.5*$J$6^2)*$G$7+($J$6*SQRT($G$7)*_xlfn.NORM.S.INV(RAND()))) -> 3.0751421 | O7: =O6*EXP(($G$6-0.5*$J$6^2)*$G$7+($J$6*SQRT($G$7)*_xlfn.NORM.S.INV(RAND()))) -> 2.9262051 | P7: =P6*EXP(($G$6-0.5*$J$6^2)*$G$7+($J$6*SQRT($G$7)*_xlfn.NORM.S.INV(RAND()))) -> 2.9612039 | Q7: =Q6*EXP(($G$6-0.5*$J$6^2)*$G$7+($J$6*SQRT($G$7)*_xlfn.NORM.S.INV(RAND()))) -> 2.9512719 | R7: =R6*EXP(($G$6-0.5*$J$6^2)*$G$7+($J$6*SQRT($G$7)*_xlfn.NORM.S.INV(RAND()))) -> 2.9699209 | S7: =S6*EXP(($G$6-0.5*$J$6^2)*$G$7+($J$6*SQRT($G$7)*_xlfn.NORM.S.INV(RAND()))) -> 2.9980364 | T7: =T6*EXP(($G$6-0.5*$J$6^2)*$G$7+($J$6*SQRT($G$7)*_xlfn.NORM.S.INV(RAND()))) -> 3.1306639 | ... AZ7: =AZ6*EXP(($G$6-0.5*$J$6^2)*$G$7+($J$6*SQRT($G$7)*_xlfn.NORM.S.INV(RAND()))) -> 2.8954589
B8: 45699 | C8: 413.45001 | D8: =LN(C8/C7) -> -0.037036816 | L8: Day 4 | M8: =M7*EXP(($G$6-0.5*$J$6^2)*$G$7+($J$6*SQRT($G$7)*_xlfn.NORM.S.INV(RAND()))) -> 2.8345067 | N8: =N7*EXP(($G$6-0.5*$J$6^2)*$G$7+($J$6*SQRT($G$7)*_xlfn.NORM.S.INV(RAND()))) -> 3.0207281 | O8: =O7*EXP(($G$6-0.5*$J$6^2)*$G$7+($J$6*SQRT($G$7)*_xlfn.NORM.S.INV(RAND()))) -> 2.8838257 | P8: =P7*EXP(($G$6-0.5*$J$6^2)*$G$7+($J$6*SQRT($G$7)*_xlfn.NORM.S.INV(RAND()))) -> 2.9542041 | Q8: =Q7*EXP(($G$6-0.5*$J$6^2)*$G$7+($J$6*SQRT($G$7)*_xlfn.NORM.S.INV(RAND()))) -> 2.8437528 | R8: =R7*EXP(($G$6-0.5*$J$6^2)*$G$7+($J$6*SQRT($G$7)*_xlfn.NORM.S.INV(RAND()))) -> 3.1037243 | S8: =S7*EXP(($G$6-0.5*$J$6^2)*$G$7+($J$6*SQRT($G$7)*_xlfn.NORM.S.INV(RAND()))) -> 3.0091515 | T8: =T7*EXP(($G$6-0.5*$J$6^2)*$G$7+($J$6*SQRT($G$7)*_xlfn.NORM.S.INV(RAND()))) -> 3.2447233 | ... AZ8: =AZ7*EXP(($G$6-0.5*$J$6^2)*$G$7+($J$6*SQRT($G$7)*_xlfn.NORM.S.INV(RAND()))) -> 3.030993
B9: 45700 | C9: 431.79999 | D9: =LN(C9/C8) -> 0.043425872 | F9: Stochastic Summary Statistics | L9: Day 5 | M9: =M8*EXP(($G$6-0.5*$J$6^2)*$G$7+($J$6*SQRT($G$7)*_xlfn.NORM.S.INV(RAND()))) -> 2.9417748 | N9: =N8*EXP(($G$6-0.5*$J$6^2)*$G$7+($J$6*SQRT($G$7)*_xlfn.NORM.S.INV(RAND()))) -> 3.0829799 | O9: =O8*EXP(($G$6-0.5*$J$6^2)*$G$7+($J$6*SQRT($G$7)*_xlfn.NORM.S.INV(RAND()))) -> 2.9435659 | P9: =P8*EXP(($G$6-0.5*$J$6^2)*$G$7+($J$6*SQRT($G$7)*_xlfn.NORM.S.INV(RAND()))) -> 3.0388066 | Q9: =Q8*EXP(($G$6-0.5*$J$6^2)*$G$7+($J$6*SQRT($G$7)*_xlfn.NORM.S.INV(RAND()))) -> 2.8592605 | R9: =R8*EXP(($G$6-0.5*$J$6^2)*$G$7+($J$6*SQRT($G$7)*_xlfn.NORM.S.INV(RAND()))) -> 3.0589123 | S9: =S8*EXP(($G$6-0.5*$J$6^2)*$G$7+($J$6*SQRT($G$7)*_xlfn.NORM.S.INV(RAND()))) -> 2.9308773 | T9: =T8*EXP(($G$6-0.5*$J$6^2)*$G$7+($J$6*SQRT($G$7)*_xlfn.NORM.S.INV(RAND()))) -> 3.14494 | ... AZ9: =AZ8*EXP(($G$6-0.5*$J$6^2)*$G$7+($J$6*SQRT($G$7)*_xlfn.NORM.S.INV(RAND()))) -> 3.169228
B10: 45701 | C10: 438.89999 | D10: =LN(C10/C9) -> 0.016309093 | F10: Tommorow Price | J10: =G5*EXP((G6-0.5*J6^2)*G7+(J6*SQRT(G7)*_xlfn.NORM.S.INV(RAND()))) -> 2.9522867 | L10: Day 6 | M10: =M9*EXP(($G$6-0.5*$J$6^2)*$G$7+($J$6*SQRT($G$7)*_xlfn.NORM.S.INV(RAND()))) -> 2.9959489 | N10: =N9*EXP(($G$6-0.5*$J$6^2)*$G$7+($J$6*SQRT($G$7)*_xlfn.NORM.S.INV(RAND()))) -> 3.1428526 | O10: =O9*EXP(($G$6-0.5*$J$6^2)*$G$7+($J$6*SQRT($G$7)*_xlfn.NORM.S.INV(RAND()))) -> 2.9137516 | P10: =P9*EXP(($G$6-0.5*$J$6^2)*$G$7+($J$6*SQRT($G$7)*_xlfn.NORM.S.INV(RAND()))) -> 2.9927132 | Q10: =Q9*EXP(($G$6-0.5*$J$6^2)*$G$7+($J$6*SQRT($G$7)*_xlfn.NORM.S.INV(RAND()))) -> 2.8995088 | R10: =R9*EXP(($G$6-0.5*$J$6^2)*$G$7+($J$6*SQRT($G$7)*_xlfn.NORM.S.INV(RAND()))) -> 2.9723858 | S10: =S9*EXP(($G$6-0.5*$J$6^2)*$G$7+($J$6*SQRT($G$7)*_xlfn.NORM.S.INV(RAND()))) -> 2.7360949 | T10: =T9*EXP(($G$6-0.5*$J$6^2)*$G$7+($J$6*SQRT($G$7)*_xlfn.NORM.S.INV(RAND()))) -> 3.1281386 | ... AZ10: =AZ9*EXP(($G$6-0.5*$J$6^2)*$G$7+($J$6*SQRT($G$7)*_xlfn.NORM.S.INV(RAND()))) -> 3.2158565
B11: 45702 | C11: 419.75 | D11: =LN(C11/C10) -> -0.044612287 | F11: Expected Future Spot | J11: =AVERAGE(M5:AZ130) -> 2.9987364 | L11: Day 7 | M11: =M10*EXP(($G$6-0.5*$J$6^2)*$G$7+($J$6*SQRT($G$7)*_xlfn.NORM.S.INV(RAND()))) -> 2.9766106 | N11: =N10*EXP(($G$6-0.5*$J$6^2)*$G$7+($J$6*SQRT($G$7)*_xlfn.NORM.S.INV(RAND()))) -> 3.0684051 | O11: =O10*EXP(($G$6-0.5*$J$6^2)*$G$7+($J$6*SQRT($G$7)*_xlfn.NORM.S.INV(RAND()))) -> 2.9378831 | P11: =P10*EXP(($G$6-0.5*$J$6^2)*$G$7+($J$6*SQRT($G$7)*_xlfn.NORM.S.INV(RAND()))) -> 2.9171582 | Q11: =Q10*EXP(($G$6-0.5*$J$6^2)*$G$7+($J$6*SQRT($G$7)*_xlfn.NORM.S.INV(RAND()))) -> 2.8271727 | R11: =R10*EXP(($G$6-0.5*$J$6^2)*$G$7+($J$6*SQRT($G$7)*_xlfn.NORM.S.INV(RAND()))) -> 3.0344606 | S11: =S10*EXP(($G$6-0.5*$J$6^2)*$G$7+($J$6*SQRT($G$7)*_xlfn.NORM.S.INV(RAND()))) -> 2.6820667 | T11: =T10*EXP(($G$6-0.5*$J$6^2)*$G$7+($J$6*SQRT($G$7)*_xlfn.NORM.S.INV(RAND()))) -> 3.2069608 | ... AZ11: =AZ10*EXP(($G$6-0.5*$J$6^2)*$G$7+($J$6*SQRT($G$7)*_xlfn.NORM.S.INV(RAND()))) -> 3.3092623
B12: 45706 | C12: 419 | D12: =LN(C12/C11) -> -0.001788376 | F12: Best Case | J12: =MAX(M5:AZ130) -> 5.7563136 | L12: Day 8 | M12: =M11*EXP(($G$6-0.5*$J$6^2)*$G$7+($J$6*SQRT($G$7)*_xlfn.NORM.S.INV(RAND()))) -> 3.0852737 | N12: =N11*EXP(($G$6-0.5*$J$6^2)*$G$7+($J$6*SQRT($G$7)*_xlfn.NORM.S.INV(RAND()))) -> 3.1163884 | O12: =O11*EXP(($G$6-0.5*$J$6^2)*$G$7+($J$6*SQRT($G$7)*_xlfn.NORM.S.INV(RAND()))) -> 2.9649511 | P12: =P11*EXP(($G$6-0.5*$J$6^2)*$G$7+($J$6*SQRT($G$7)*_xlfn.NORM.S.INV(RAND()))) -> 3.0706649 | Q12: =Q11*EXP(($G$6-0.5*$J$6^2)*$G$7+($J$6*SQRT($G$7)*_xlfn.NORM.S.INV(RAND()))) -> 2.8799385 | R12: =R11*EXP(($G$6-0.5*$J$6^2)*$G$7+($J$6*SQRT($G$7)*_xlfn.NORM.S.INV(RAND()))) -> 2.9560993 | S12: =S11*EXP(($G$6-0.5*$J$6^2)*$G$7+($J$6*SQRT($G$7)*_xlfn.NORM.S.INV(RAND()))) -> 2.5994578 | T12: =T11*EXP(($G$6-0.5*$J$6^2)*$G$7+($J$6*SQRT($G$7)*_xlfn.NORM.S.INV(RAND()))) -> 3.2568592 | ... AZ12: =AZ11*EXP(($G$6-0.5*$J$6^2)*$G$7+($J$6*SQRT($G$7)*_xlfn.NORM.S.INV(RAND()))) -> 3.3050803
B13: 45707 | C13: 417.89999 | D13: =LN(C13/C12) -> -0.0026287651 | F13: Worst Case | J13: =MIN(M5:AZ130) -> 1.5607483 | L13: Day 9 | M13: =M12*EXP(($G$6-0.5*$J$6^2)*$G$7+($J$6*SQRT($G$7)*_xlfn.NORM.S.INV(RAND()))) -> 2.9075187 | N13: =N12*EXP(($G$6-0.5*$J$6^2)*$G$7+($J$6*SQRT($G$7)*_xlfn.NORM.S.INV(RAND()))) -> 3.1042587 | O13: =O12*EXP(($G$6-0.5*$J$6^2)*$G$7+($J$6*SQRT($G$7)*_xlfn.NORM.S.INV(RAND()))) -> 2.8999226 | P13: =P12*EXP(($G$6-0.5*$J$6^2)*$G$7+($J$6*SQRT($G$7)*_xlfn.NORM.S.INV(RAND()))) -> 3.0887082 | Q13: =Q12*EXP(($G$6-0.5*$J$6^2)*$G$7+($J$6*SQRT($G$7)*_xlfn.NORM.S.INV(RAND()))) -> 2.9720635 | R13: =R12*EXP(($G$6-0.5*$J$6^2)*$G$7+($J$6*SQRT($G$7)*_xlfn.NORM.S.INV(RAND()))) -> 2.9865923 | S13: =S12*EXP(($G$6-0.5*$J$6^2)*$G$7+($J$6*SQRT($G$7)*_xlfn.NORM.S.INV(RAND()))) -> 2.7131752 | T13: =T12*EXP(($G$6-0.5*$J$6^2)*$G$7+($J$6*SQRT($G$7)*_xlfn.NORM.S.INV(RAND()))) -> 3.311242 | ... AZ13: =AZ12*EXP(($G$6-0.5*$J$6^2)*$G$7+($J$6*SQRT($G$7)*_xlfn.NORM.S.INV(RAND()))) -> 3.36531
B14: 45708 | C14: 395.75 | D14: =LN(C14/C13) -> -0.054459456 | F14: In-The-Money Probability | J14: =COUNTIF(M130:AZ130,">2.95")/COUNT(M130:AZ130) -> 0.45 | L14: Day 10 | M14: =M13*EXP(($G$6-0.5*$J$6^2)*$G$7+($J$6*SQRT($G$7)*_xlfn.NORM.S.INV(RAND()))) -> 2.8878724 | N14: =N13*EXP(($G$6-0.5*$J$6^2)*$G$7+($J$6*SQRT($G$7)*_xlfn.NORM.S.INV(RAND()))) -> 3.174449 | O14: =O13*EXP(($G$6-0.5*$J$6^2)*$G$7+($J$6*SQRT($G$7)*_xlfn.NORM.S.INV(RAND()))) -> 2.9502562 | P14: =P13*EXP(($G$6-0.5*$J$6^2)*$G$7+($J$6*SQRT($G$7)*_xlfn.NORM.S.INV(RAND()))) -> 2.9236954 | Q14: =Q13*EXP(($G$6-0.5*$J$6^2)*$G$7+($J$6*SQRT($G$7)*_xlfn.NORM.S.INV(RAND()))) -> 2.8959368 | R14: =R13*EXP(($G$6-0.5*$J$6^2)*$G$7+($J$6*SQRT($G$7)*_xlfn.NORM.S.INV(RAND()))) -> 2.9462187 | S14: =S13*EXP(($G$6-0.5*$J$6^2)*$G$7+($J$6*SQRT($G$7)*_xlfn.NORM.S.INV(RAND()))) -> 2.6426808 | T14: =T13*EXP(($G$6-0.5*$J$6^2)*$G$7+($J$6*SQRT($G$7)*_xlfn.NORM.S.INV(RAND()))) -> 3.2327389 | ... AZ14: =AZ13*EXP(($G$6-0.5*$J$6^2)*$G$7+($J$6*SQRT($G$7)*_xlfn.NORM.S.INV(RAND()))) -> 3.3499592
B15: 45709 | C15: 400 | D15: =LN(C15/C14) -> 0.010681848 | L15: Day 11 | M15: =M14*EXP(($G$6-0.5*$J$6^2)*$G$7+($J$6*SQRT($G$7)*_xlfn.NORM.S.INV(RAND()))) -> 2.7224512 | N15: =N14*EXP(($G$6-0.5*$J$6^2)*$G$7+($J$6*SQRT($G$7)*_xlfn.NORM.S.INV(RAND()))) -> 3.1300916 | O15: =O14*EXP(($G$6-0.5*$J$6^2)*$G$7+($J$6*SQRT($G$7)*_xlfn.NORM.S.INV(RAND()))) -> 2.9218606 | P15: =P14*EXP(($G$6-0.5*$J$6^2)*$G$7+($J$6*SQRT($G$7)*_xlfn.NORM.S.INV(RAND()))) -> 2.8257846 | Q15: =Q14*EXP(($G$6-0.5*$J$6^2)*$G$7+($J$6*SQRT($G$7)*_xlfn.NORM.S.INV(RAND()))) -> 2.8168489 | R15: =R14*EXP(($G$6-0.5*$J$6^2)*$G$7+($J$6*SQRT($G$7)*_xlfn.NORM.S.INV(RAND()))) -> 3.1616215 | S15: =S14*EXP(($G$6-0.5*$J$6^2)*$G$7+($J$6*SQRT($G$7)*_xlfn.NORM.S.INV(RAND()))) -> 2.5725529 | T15: =T14*EXP(($G$6-0.5*$J$6^2)*$G$7+($J$6*SQRT($G$7)*_xlfn.NORM.S.INV(RAND()))) -> 3.2017665 | ... AZ15: =AZ14*EXP(($G$6-0.5*$J$6^2)*$G$7+($J$6*SQRT($G$7)*_xlfn.NORM.S.INV(RAND()))) -> 3.3644587
B16: 45712 | C16: 393.79999 | D16: =LN(C16/C15) -> -0.015621412 | L16: Day 12 | M16: =M15*EXP(($G$6-0.5*$J$6^2)*$G$7+($J$6*SQRT($G$7)*_xlfn.NORM.S.INV(RAND()))) -> 2.6509819 | N16: =N15*EXP(($G$6-0.5*$J$6^2)*$G$7+($J$6*SQRT($G$7)*_xlfn.NORM.S.INV(RAND()))) -> 3.1846174 | O16: =O15*EXP(($G$6-0.5*$J$6^2)*$G$7+($J$6*SQRT($G$7)*_xlfn.NORM.S.INV(RAND()))) -> 2.9832711 | P16: =P15*EXP(($G$6-0.5*$J$6^2)*$G$7+($J$6*SQRT($G$7)*_xlfn.NORM.S.INV(RAND()))) -> 2.7725697 | Q16: =Q15*EXP(($G$6-0.5*$J$6^2)*$G$7+($J$6*SQRT($G$7)*_xlfn.NORM.S.INV(RAND()))) -> 2.8626513 | R16: =R15*EXP(($G$6-0.5*$J$6^2)*$G$7+($J$6*SQRT($G$7)*_xlfn.NORM.S.INV(RAND()))) -> 3.2043179 | S16: =S15*EXP(($G$6-0.5*$J$6^2)*$G$7+($J$6*SQRT($G$7)*_xlfn.NORM.S.INV(RAND()))) -> 2.468828 | T16: =T15*EXP(($G$6-0.5*$J$6^2)*$G$7+($J$6*SQRT($G$7)*_xlfn.NORM.S.INV(RAND()))) -> 3.1695954 | ... AZ16: =AZ15*EXP(($G$6-0.5*$J$6^2)*$G$7+($J$6*SQRT($G$7)*_xlfn.NORM.S.INV(RAND()))) -> 3.3297341
B17: 45713 | C17: 380.5 | D17: =LN(C17/C16) -> -0.034356958 | L17: Day 13 | M17: =M16*EXP(($G$6-0.5*$J$6^2)*$G$7+($J$6*SQRT($G$7)*_xlfn.NORM.S.INV(RAND()))) -> 2.6010771 | N17: =N16*EXP(($G$6-0.5*$J$6^2)*$G$7+($J$6*SQRT($G$7)*_xlfn.NORM.S.INV(RAND()))) -> 3.3105479 | O17: =O16*EXP(($G$6-0.5*$J$6^2)*$G$7+($J$6*SQRT($G$7)*_xlfn.NORM.S.INV(RAND()))) -> 2.9970823 | P17: =P16*EXP(($G$6-0.5*$J$6^2)*$G$7+($J$6*SQRT($G$7)*_xlfn.NORM.S.INV(RAND()))) -> 2.7189009 | Q17: =Q16*EXP(($G$6-0.5*$J$6^2)*$G$7+($J$6*SQRT($G$7)*_xlfn.NORM.S.INV(RAND()))) -> 2.6976818 | R17: =R16*EXP(($G$6-0.5*$J$6^2)*$G$7+($J$6*SQRT($G$7)*_xlfn.NORM.S.INV(RAND()))) -> 3.1895452 | S17: =S16*EXP(($G$6-0.5*$J$6^2)*$G$7+($J$6*SQRT($G$7)*_xlfn.NORM.S.INV(RAND()))) -> 2.4327459 | T17: =T16*EXP(($G$6-0.5*$J$6^2)*$G$7+($J$6*SQRT($G$7)*_xlfn.NORM.S.INV(RAND()))) -> 3.2372287 | ... AZ17: =AZ16*EXP(($G$6-0.5*$J$6^2)*$G$7+($J$6*SQRT($G$7)*_xlfn.NORM.S.INV(RAND()))) -> 3.421092
B18: 45714 | C18: 379.45001 | D18: =LN(C18/C17) -> -0.0027633093 | L18: Day 14 | M18: =M17*EXP(($G$6-0.5*$J$6^2)*$G$7+($J$6*SQRT($G$7)*_xlfn.NORM.S.INV(RAND()))) -> 2.6282972 | N18: =N17*EXP(($G$6-0.5*$J$6^2)*$G$7+($J$6*SQRT($G$7)*_xlfn.NORM.S.INV(RAND()))) -> 3.3214524 | O18: =O17*EXP(($G$6-0.5*$J$6^2)*$G$7+($J$6*SQRT($G$7)*_xlfn.NORM.S.INV(RAND()))) -> 3.0672279 | P18: =P17*EXP(($G$6-0.5*$J$6^2)*$G$7+($J$6*SQRT($G$7)*_xlfn.NORM.S.INV(RAND()))) -> 2.6660818 | Q18: =Q17*EXP(($G$6-0.5*$J$6^2)*$G$7+($J$6*SQRT($G$7)*_xlfn.NORM.S.INV(RAND()))) -> 2.6773038 | R18: =R17*EXP(($G$6-0.5*$J$6^2)*$G$7+($J$6*SQRT($G$7)*_xlfn.NORM.S.INV(RAND()))) -> 3.1855583 | S18: =S17*EXP(($G$6-0.5*$J$6^2)*$G$7+($J$6*SQRT($G$7)*_xlfn.NORM.S.INV(RAND()))) -> 2.4191359 | T18: =T17*EXP(($G$6-0.5*$J$6^2)*$G$7+($J$6*SQRT($G$7)*_xlfn.NORM.S.INV(RAND()))) -> 3.2651485 | ... AZ18: =AZ17*EXP(($G$6-0.5*$J$6^2)*$G$7+($J$6*SQRT($G$7)*_xlfn.NORM.S.INV(RAND()))) -> 3.4229465
B19: 45715 | C19: 378.75 | D19: =LN(C19/C18) -> -0.0018465112 | L19: Day 15 | M19: =M18*EXP(($G$6-0.5*$J$6^2)*$G$7+($J$6*SQRT($G$7)*_xlfn.NORM.S.INV(RAND()))) -> 2.6190004 | N19: =N18*EXP(($G$6-0.5*$J$6^2)*$G$7+($J$6*SQRT($G$7)*_xlfn.NORM.S.INV(RAND()))) -> 3.2117781 | O19: =O18*EXP(($G$6-0.5*$J$6^2)*$G$7+($J$6*SQRT($G$7)*_xlfn.NORM.S.INV(RAND()))) -> 3.1679369 | P19: =P18*EXP(($G$6-0.5*$J$6^2)*$G$7+($J$6*SQRT($G$7)*_xlfn.NORM.S.INV(RAND()))) -> 2.6881443 | Q19: =Q18*EXP(($G$6-0.5*$J$6^2)*$G$7+($J$6*SQRT($G$7)*_xlfn.NORM.S.INV(RAND()))) -> 2.6342761 | R19: =R18*EXP(($G$6-0.5*$J$6^2)*$G$7+($J$6*SQRT($G$7)*_xlfn.NORM.S.INV(RAND()))) -> 3.2293376 | S19: =S18*EXP(($G$6-0.5*$J$6^2)*$G$7+($J$6*SQRT($G$7)*_xlfn.NORM.S.INV(RAND()))) -> 2.346509 | T19: =T18*EXP(($G$6-0.5*$J$6^2)*$G$7+($J$6*SQRT($G$7)*_xlfn.NORM.S.INV(RAND()))) -> 3.2989911 | ... AZ19: =AZ18*EXP(($G$6-0.5*$J$6^2)*$G$7+($J$6*SQRT($G$7)*_xlfn.NORM.S.INV(RAND()))) -> 3.2908134
B20: 45716 | C20: 379.04999 | D20: =LN(C20/C19) -> 0.00079173347 | L20: Day 16 | M20: =M19*EXP(($G$6-0.5*$J$6^2)*$G$7+($J$6*SQRT($G$7)*_xlfn.NORM.S.INV(RAND()))) -> 2.5399249 | N20: =N19*EXP(($G$6-0.5*$J$6^2)*$G$7+($J$6*SQRT($G$7)*_xlfn.NORM.S.INV(RAND()))) -> 3.2543931 | O20: =O19*EXP(($G$6-0.5*$J$6^2)*$G$7+($J$6*SQRT($G$7)*_xlfn.NORM.S.INV(RAND()))) -> 3.1883128 | P20: =P19*EXP(($G$6-0.5*$J$6^2)*$G$7+($J$6*SQRT($G$7)*_xlfn.NORM.S.INV(RAND()))) -> 2.7341547 | Q20: =Q19*EXP(($G$6-0.5*$J$6^2)*$G$7+($J$6*SQRT($G$7)*_xlfn.NORM.S.INV(RAND()))) -> 2.5719306 | R20: =R19*EXP(($G$6-0.5*$J$6^2)*$G$7+($J$6*SQRT($G$7)*_xlfn.NORM.S.INV(RAND()))) -> 3.2924024 | S20: =S19*EXP(($G$6-0.5*$J$6^2)*$G$7+($J$6*SQRT($G$7)*_xlfn.NORM.S.INV(RAND()))) -> 2.1559976 | T20: =T19*EXP(($G$6-0.5*$J$6^2)*$G$7+($J$6*SQRT($G$7)*_xlfn.NORM.S.INV(RAND()))) -> 3.3751833 | ... AZ20: =AZ19*EXP(($G$6-0.5*$J$6^2)*$G$7+($J$6*SQRT($G$7)*_xlfn.NORM.S.INV(RAND()))) -> 3.3091688
B21: 45719 | C21: 392.70001 | D21: =LN(C21/C20) -> 0.035377902 | L21: Day 17 | M21: =M20*EXP(($G$6-0.5*$J$6^2)*$G$7+($J$6*SQRT($G$7)*_xlfn.NORM.S.INV(RAND()))) -> 2.5594455 | N21: =N20*EXP(($G$6-0.5*$J$6^2)*$G$7+($J$6*SQRT($G$7)*_xlfn.NORM.S.INV(RAND()))) -> 3.1344137 | O21: =O20*EXP(($G$6-0.5*$J$6^2)*$G$7+($J$6*SQRT($G$7)*_xlfn.NORM.S.INV(RAND()))) -> 3.4578233 | P21: =P20*EXP(($G$6-0.5*$J$6^2)*$G$7+($J$6*SQRT($G$7)*_xlfn.NORM.S.INV(RAND()))) -> 2.7429059 | Q21: =Q20*EXP(($G$6-0.5*$J$6^2)*$G$7+($J$6*SQRT($G$7)*_xlfn.NORM.S.INV(RAND()))) -> 2.4854017 | R21: =R20*EXP(($G$6-0.5*$J$6^2)*$G$7+($J$6*SQRT($G$7)*_xlfn.NORM.S.INV(RAND()))) -> 3.3875165 | S21: =S20*EXP(($G$6-0.5*$J$6^2)*$G$7+($J$6*SQRT($G$7)*_xlfn.NORM.S.INV(RAND()))) -> 2.1710683 | T21: =T20*EXP(($G$6-0.5*$J$6^2)*$G$7+($J$6*SQRT($G$7)*_xlfn.NORM.S.INV(RAND()))) -> 3.4608836 | ... AZ21: =AZ20*EXP(($G$6-0.5*$J$6^2)*$G$7+($J$6*SQRT($G$7)*_xlfn.NORM.S.INV(RAND()))) -> 3.3315088
B22: 45720 | C22: 403.75 | D22: =LN(C22/C21) -> 0.027749882 | L22: Day 18 | M22: =M21*EXP(($G$6-0.5*$J$6^2)*$G$7+($J$6*SQRT($G$7)*_xlfn.NORM.S.INV(RAND()))) -> 2.596202 | N22: =N21*EXP(($G$6-0.5*$J$6^2)*$G$7+($J$6*SQRT($G$7)*_xlfn.NORM.S.INV(RAND()))) -> 3.0940476 | O22: =O21*EXP(($G$6-0.5*$J$6^2)*$G$7+($J$6*SQRT($G$7)*_xlfn.NORM.S.INV(RAND()))) -> 3.5328552 | P22: =P21*EXP(($G$6-0.5*$J$6^2)*$G$7+($J$6*SQRT($G$7)*_xlfn.NORM.S.INV(RAND()))) -> 2.7342085 | Q22: =Q21*EXP(($G$6-0.5*$J$6^2)*$G$7+($J$6*SQRT($G$7)*_xlfn.NORM.S.INV(RAND()))) -> 2.5430913 | R22: =R21*EXP(($G$6-0.5*$J$6^2)*$G$7+($J$6*SQRT($G$7)*_xlfn.NORM.S.INV(RAND()))) -> 3.3835514 | S22: =S21*EXP(($G$6-0.5*$J$6^2)*$G$7+($J$6*SQRT($G$7)*_xlfn.NORM.S.INV(RAND()))) -> 2.1279619 | T22: =T21*EXP(($G$6-0.5*$J$6^2)*$G$7+($J$6*SQRT($G$7)*_xlfn.NORM.S.INV(RAND()))) -> 3.4321857 | ... AZ22: =AZ21*EXP(($G$6-0.5*$J$6^2)*$G$7+($J$6*SQRT($G$7)*_xlfn.NORM.S.INV(RAND()))) -> 3.3444761
B23: 45721 | C23: 415.5 | D23: =LN(C23/C22) -> 0.02868674 | L23: Day 19 | M23: =M22*EXP(($G$6-0.5*$J$6^2)*$G$7+($J$6*SQRT($G$7)*_xlfn.NORM.S.INV(RAND()))) -> 2.4953955 | N23: =N22*EXP(($G$6-0.5*$J$6^2)*$G$7+($J$6*SQRT($G$7)*_xlfn.NORM.S.INV(RAND()))) -> 3.1814227 | O23: =O22*EXP(($G$6-0.5*$J$6^2)*$G$7+($J$6*SQRT($G$7)*_xlfn.NORM.S.INV(RAND()))) -> 3.4122731 | P23: =P22*EXP(($G$6-0.5*$J$6^2)*$G$7+($J$6*SQRT($G$7)*_xlfn.NORM.S.INV(RAND()))) -> 2.7831721 | Q23: =Q22*EXP(($G$6-0.5*$J$6^2)*$G$7+($J$6*SQRT($G$7)*_xlfn.NORM.S.INV(RAND()))) -> 2.5212809 | R23: =R22*EXP(($G$6-0.5*$J$6^2)*$G$7+($J$6*SQRT($G$7)*_xlfn.NORM.S.INV(RAND()))) -> 3.5110993 | S23: =S22*EXP(($G$6-0.5*$J$6^2)*$G$7+($J$6*SQRT($G$7)*_xlfn.NORM.S.INV(RAND()))) -> 2.0503321 | T23: =T22*EXP(($G$6-0.5*$J$6^2)*$G$7+($J$6*SQRT($G$7)*_xlfn.NORM.S.INV(RAND()))) -> 3.498891 | ... AZ23: =AZ22*EXP(($G$6-0.5*$J$6^2)*$G$7+($J$6*SQRT($G$7)*_xlfn.NORM.S.INV(RAND()))) -> 3.2281107
B24: 45722 | C24: 393 | D24: =LN(C24/C23) -> -0.055673002 | L24: Day 20 | M24: =M23*EXP(($G$6-0.5*$J$6^2)*$G$7+($J$6*SQRT($G$7)*_xlfn.NORM.S.INV(RAND()))) -> 2.5368365 | N24: =N23*EXP(($G$6-0.5*$J$6^2)*$G$7+($J$6*SQRT($G$7)*_xlfn.NORM.S.INV(RAND()))) -> 3.1284235 | O24: =O23*EXP(($G$6-0.5*$J$6^2)*$G$7+($J$6*SQRT($G$7)*_xlfn.NORM.S.INV(RAND()))) -> 3.4660323 | P24: =P23*EXP(($G$6-0.5*$J$6^2)*$G$7+($J$6*SQRT($G$7)*_xlfn.NORM.S.INV(RAND()))) -> 2.7005674 | Q24: =Q23*EXP(($G$6-0.5*$J$6^2)*$G$7+($J$6*SQRT($G$7)*_xlfn.NORM.S.INV(RAND()))) -> 2.4977301 | R24: =R23*EXP(($G$6-0.5*$J$6^2)*$G$7+($J$6*SQRT($G$7)*_xlfn.NORM.S.INV(RAND()))) -> 3.5968386 | S24: =S23*EXP(($G$6-0.5*$J$6^2)*$G$7+($J$6*SQRT($G$7)*_xlfn.NORM.S.INV(RAND()))) -> 2.0298746 | T24: =T23*EXP(($G$6-0.5*$J$6^2)*$G$7+($J$6*SQRT($G$7)*_xlfn.NORM.S.INV(RAND()))) -> 3.5556735 | ... AZ24: =AZ23*EXP(($G$6-0.5*$J$6^2)*$G$7+($J$6*SQRT($G$7)*_xlfn.NORM.S.INV(RAND()))) -> 3.3455472
B25: 45723 | C25: 390.20001 | D25: =LN(C25/C24) -> -0.0071501524 | L25: Day 21 | M25: =M24*EXP(($G$6-0.5*$J$6^2)*$G$7+($J$6*SQRT($G$7)*_xlfn.NORM.S.INV(RAND()))) -> 2.5488704 | N25: =N24*EXP(($G$6-0.5*$J$6^2)*$G$7+($J$6*SQRT($G$7)*_xlfn.NORM.S.INV(RAND()))) -> 2.9960215 | O25: =O24*EXP(($G$6-0.5*$J$6^2)*$G$7+($J$6*SQRT($G$7)*_xlfn.NORM.S.INV(RAND()))) -> 3.5362551 | P25: =P24*EXP(($G$6-0.5*$J$6^2)*$G$7+($J$6*SQRT($G$7)*_xlfn.NORM.S.INV(RAND()))) -> 2.6695589 | Q25: =Q24*EXP(($G$6-0.5*$J$6^2)*$G$7+($J$6*SQRT($G$7)*_xlfn.NORM.S.INV(RAND()))) -> 2.4434874 | R25: =R24*EXP(($G$6-0.5*$J$6^2)*$G$7+($J$6*SQRT($G$7)*_xlfn.NORM.S.INV(RAND()))) -> 3.6036128 | S25: =S24*EXP(($G$6-0.5*$J$6^2)*$G$7+($J$6*SQRT($G$7)*_xlfn.NORM.S.INV(RAND()))) -> 1.9998721 | T25: =T24*EXP(($G$6-0.5*$J$6^2)*$G$7+($J$6*SQRT($G$7)*_xlfn.NORM.S.INV(RAND()))) -> 3.4272923 | ... AZ25: =AZ24*EXP(($G$6-0.5*$J$6^2)*$G$7+($J$6*SQRT($G$7)*_xlfn.NORM.S.INV(RAND()))) -> 3.5217358
B26: 45726 | C26: 389.35001 | D26: =LN(C26/C25) -> -0.0021807618 | L26: Day 22 | M26: =M25*EXP(($G$6-0.5*$J$6^2)*$G$7+($J$6*SQRT($G$7)*_xlfn.NORM.S.INV(RAND()))) -> 2.4703352 | N26: =N25*EXP(($G$6-0.5*$J$6^2)*$G$7+($J$6*SQRT($G$7)*_xlfn.NORM.S.INV(RAND()))) -> 3.0475578 | O26: =O25*EXP(($G$6-0.5*$J$6^2)*$G$7+($J$6*SQRT($G$7)*_xlfn.NORM.S.INV(RAND()))) -> 3.5100097 | P26: =P25*EXP(($G$6-0.5*$J$6^2)*$G$7+($J$6*SQRT($G$7)*_xlfn.NORM.S.INV(RAND()))) -> 2.6478309 | Q26: =Q25*EXP(($G$6-0.5*$J$6^2)*$G$7+($J$6*SQRT($G$7)*_xlfn.NORM.S.INV(RAND()))) -> 2.4976324 | R26: =R25*EXP(($G$6-0.5*$J$6^2)*$G$7+($J$6*SQRT($G$7)*_xlfn.NORM.S.INV(RAND()))) -> 3.4875511 | S26: =S25*EXP(($G$6-0.5*$J$6^2)*$G$7+($J$6*SQRT($G$7)*_xlfn.NORM.S.INV(RAND()))) -> 2.0676323 | T26: =T25*EXP(($G$6-0.5*$J$6^2)*$G$7+($J$6*SQRT($G$7)*_xlfn.NORM.S.INV(RAND()))) -> 3.3347434 | ... AZ26: =AZ25*EXP(($G$6-0.5*$J$6^2)*$G$7+($J$6*SQRT($G$7)*_xlfn.NORM.S.INV(RAND()))) -> 3.3884268
... B130: 45875 | C130: 293.39999 | D130: =LN(C130/C129) -> -0.017902921 | L130: Day 126 | M130: =M129*EXP(($G$6-0.5*$J$6^2)*$G$7+($J$6*SQRT($G$7)*_xlfn.NORM.S.INV(RAND()))) -> 2.6186661 | N130: =N129*EXP(($G$6-0.5*$J$6^2)*$G$7+($J$6*SQRT($G$7)*_xlfn.NORM.S.INV(RAND()))) -> 3.4624735 | O130: =O129*EXP(($G$6-0.5*$J$6^2)*$G$7+($J$6*SQRT($G$7)*_xlfn.NORM.S.INV(RAND()))) -> 3.6747175 | P130: =P129*EXP(($G$6-0.5*$J$6^2)*$G$7+($J$6*SQRT($G$7)*_xlfn.NORM.S.INV(RAND()))) -> 3.5723997 | Q130: =Q129*EXP(($G$6-0.5*$J$6^2)*$G$7+($J$6*SQRT($G$7)*_xlfn.NORM.S.INV(RAND()))) -> 1.7622249 | R130: =R129*EXP(($G$6-0.5*$J$6^2)*$G$7+($J$6*SQRT($G$7)*_xlfn.NORM.S.INV(RAND()))) -> 2.9037431 | S130: =S129*EXP(($G$6-0.5*$J$6^2)*$G$7+($J$6*SQRT($G$7)*_xlfn.NORM.S.INV(RAND()))) -> 2.8439695 | T130: =T129*EXP(($G$6-0.5*$J$6^2)*$G$7+($J$6*SQRT($G$7)*_xlfn.NORM.S.INV(RAND()))) -> 4.0116885 | ... AZ130: =AZ129*EXP(($G$6-0.5*$J$6^2)*$G$7+($J$6*SQRT($G$7)*_xlfn.NORM.S.INV(RAND()))) -> 3.5085496
B131: 45876 | C131: 297.79999 | D131: =LN(C131/C130) -> 0.014885234
B132: 45877 | C132: 309.35001 | D132: =LN(C132/C131) -> 0.038051262
B133: 45880 | C133: 320.70001 | D133: =LN(C133/C132) -> 0.036032803
B134: 45881 | C134: 315.14999 | D134: =LN(C134/C133) -> -0.017457448
B135: 45882 | C135: 319.60001 | D135: =LN(C135/C134) -> 0.014021536
B136: 45883 | C136: 326.5 | D136: =LN(C136/C135) -> 0.021359716
B137: 45884 | C137: 341.64999 | D137: =LN(C137/C136) -> 0.045356855
B138: 45887 | C138: 343.60001 | D138: =LN(C138/C137) -> 0.0056914045
B139: 45888 | C139: 356.20001 | D139: =LN(C139/C138) -> 0.036014197
B140: 45889 | C140: 360.25 | D140: =LN(C140/C139) -> 0.01130583
B141: 45890 | C141: 375.25 | D141: =LN(C141/C140) -> 0.040794236
B142: 45891 | C142: 390.64999 | D142: =LN(C142/C141) -> 0.040219532
... B257: 46059 | C257: 286.70001 | D257: =LN(C257/C256) -> -0.072961206
